<?xml version="1.0"?>
<robot xmlns:xacro="http://www.ros.org/wiki/xacro"  >

    <xacro:include filename="inertial_macros.xacro"/>

    <!-- Example link -->
    <!--<link name="base_link"></link> -->

    <!-- <xacro:include filename="robot_core.xacro" /> -->

    <!-- Colores de los materiales a ocupar en el archivo URFD-->
    <material name="white">
        <color rgba="1 1 1 1" />
    </material>

    <material name="orange">
        <color rgba="1 0.3 0.1 1"/>
    </material>

    <material name="blue">
        <color rgba="0.2 0.2 1 1"/>
    </material>

    <material name="black">
        <color rgba="0 0 0 1"/>
    </material>

    <!-- CUERPO DEL ROBOT-->
    <!-- Enlace base estandar para cualquier archivo inicial de URFD-->
    <link name="base_link">

    </link>

    <!-- Union de enlace y chasis para el armado del prototipo-->
    <joint name="chasis_union" type="fixed">
        <parent link="base_link"/><!-- Clase padre-->
        <child link="chasis"/><!-- Clase hija-->
        <origin xyz="-0.1 0 0"/><!-- Centro del mundo-->
    </joint>

   

    <!-- Chasis del prototipo-->
    <link name="chasis">
         <visual>
            <origin xyz="0.15 0 0.075"/>
            <geometry>
                <box size="0.3 0.3 0.15"/>
            </geometry>
            <material name="white"/>
        </visual>
        <collision>
            <origin xyz="0.15 0 0.075"/>
            <geometry>
                <box size="0.3 0.3 0.15"/>
            </geometry>
        </collision>
        <xacro:inertial_box mass="0.5" x="0.3" y="0.3" z="0.15">
            <origin xyz="0.15 0 0.075" rpy="0 0 0"/>
        </xacro:inertial_box>
    </link>

    <!-- Valores necesarios para iniciar materiales dentro de un ambiente en Gazebo-->
    <gazebo reference="chasis">
        <material>Gazebo/White</material>
    </gazebo>


    <!-- RUEDAS DEL ROBOT-->

    <!-- Rueda Izquierda trasera-->
    <joint name="rueda_izquierda_union" type="continuous">
        <parent link="base_link"/><!-- Clase padre-->
        <child link="rueda_izq"/><!-- Clase hija-->
        <origin xyz="0 0.175 0" rpy="-${pi/2} 0 0"/><!-- Posicion de la rueda y su balanceo (rpy)-->
        <axis xyz="0 0 1"/> <!-- Sentido del giro de la rueda-->
    </joint>

    <link name="rueda_izq">
        <visual>
            <geometry>
                <cylinder radius="0.05" length="0.04"/>
            </geometry>
            <material name="blue"/>
        </visual>
        <collision>
            <geometry>
                <cylinder radius="0.05" length="0.04"/>
            </geometry>
        </collision>
        <xacro:inertial_cylinder mass="0.1" length="0.04" radius="0.05">
            <origin xyz="0 0 0" rpy="0 0 0"/>
        </xacro:inertial_cylinder>
    </link>

    <gazebo reference="rueda_izq">
        <material>
            Gazebo/Blue
        </material>
    </gazebo>

    <!-- Rueda Derecha trasera-->
    <joint name="rueda_derecha_union" type="continuous">
        <parent link="base_link"/><!-- Clase padre-->
        <child link="rueda_der"/><!-- Clase hija-->
        <origin xyz="0 -0.175 0" rpy="${pi/2} 0 0"/><!-- Centro del mundo-->
        <axis xyz="0 0 -1"/>
    </joint>

    <link name="rueda_der">
        <visual>
            <geometry>
                <cylinder radius="0.05" length="0.04"/>
            </geometry>
            <material name="blue"/>
        </visual>
        <collision>
            <geometry>
                <cylinder radius="0.05" length="0.04"/>
            </geometry>
        </collision>
        <xacro:inertial_cylinder mass="0.1" length="0.04" radius="0.05">
            <origin xyz="0 0 0" rpy="0 0 0"/>
        </xacro:inertial_cylinder>
    </link>
    <gazebo reference="rueda_der">
        <material>
            Gazebo/Blue
        </material>
    </gazebo>

    <joint name="caster_wheel_joint" type="fixed">
        <parent link="chasis"/>
        <child link="caster_wheel"/>
        <origin xyz="0.24 0 0"/>
    </joint>


    <link name="caster_wheel">
        <visual>
            <geometry>
                <sphere radius="0.05"/>
            </geometry>
            <material name="black"/>
        </visual>
        <collision>
            <geometry>
                <sphere radius="0.05"/>
            </geometry>
        </collision>
        <xacro:inertial_sphere mass="0.1" radius="0.05">
            <origin xyz="0 0 0" rpy="0 0 0"/>
        </xacro:inertial_sphere>
    </link>

    <gazebo reference="caster_wheel">
        <material>Gazebo/Black</material>
        <mu1 value="0.001"/>
        <mu2 value="0.001"/>
    </gazebo>

</robot>